Workbook

Sheet GLOSARIO
A1: ✔ Actividad de varios días
A2: ✔ Cambio de técnico de un día a otro
A3: ✔ Trabajo en grupo
A4: ✔ Saber quién estuvo cada día
A6: ¿QUÉ PASA SI UNA ACTIVIDAD DURA VARIOS DÍAS?
A8: Se mantiene una sola OT
A9: Se repite la asignación diaria
A11: No se rompe nada.
A13: CASO 1: Técnico con día libre
A15: Simple:
A16: No tiene registro en Asignación.
A17: Y en tabla Disponibilidad aparece como "Día Libre".
... A102: Facturable = Sí (según hoja 1)

Sheet master
A2: trabajos para hoy
A3: fecha
A4: tecnicos | B4: orden | C4: estado
A5: =_xlfn.XLOOKUP(B3,D11:E14,) -> #VALUE! | B5: =_xlfn.XLOOKUP(C3,E11:F14,) -> #VALUE! | C5: =_xlfn.XLOOKUP(D3,F11:G14,) -> #VALUE! | D5: =_xlfn.XLOOKUP(E3,G11:H14,) -> #VALUE!
A6: =_xlfn.XLOOKUP(B4,D12:E15,) -> #VALUE! | B6: =_xlfn.XLOOKUP(C4,E12:F15,) -> #VALUE! | C6: =_xlfn.XLOOKUP(D4,F12:G15,) -> #VALUE! | D6: =_xlfn.XLOOKUP(E4,G12:H15,) -> #VALUE!
A7: =_xlfn.XLOOKUP(B5,D13:E16,) -> #VALUE! | B7: =_xlfn.XLOOKUP(C5,E13:F16,) -> #VALUE! | C7: =_xlfn.XLOOKUP(D5,F13:G16,) -> #VALUE! | D7: =_xlfn.XLOOKUP(E5,G13:H16,) -> #VALUE!
A8: =_xlfn.XLOOKUP(B6,D14:E17,) -> #VALUE! | B8: =_xlfn.XLOOKUP(C6,E14:F17,) -> #VALUE! | C8: =_xlfn.XLOOKUP(D6,F14:G17,) -> #VALUE! | D8: =_xlfn.XLOOKUP(E6,G14:H17,) -> #VALUE!
A9: =_xlfn.XLOOKUP(B7,D15:E18,) -> #VALUE! | B9: =_xlfn.XLOOKUP(C7,E15:F18,) -> #VALUE! | C9: =_xlfn.XLOOKUP(D7,F15:G18,) -> #VALUE! | D9: =_xlfn.XLOOKUP(E7,G15:H18,) -> #VALUE!
A10: =_xlfn.XLOOKUP(B8,D16:E19,) -> #VALUE! | B10: =_xlfn.XLOOKUP(C8,E16:F19,) -> #VALUE! | C10: =_xlfn.XLOOKUP(D8,F16:G19,) -> #VALUE! | D10: =_xlfn.XLOOKUP(E8,G16:H19,) -> #VALUE!

Sheet ORDENES
A1: ID_ORDEN | B1: CIUDAD | C1: Cliente | D1: Local | E1: Tipo | F1: Fecha Inicio | G1: Fecha Fin | H1: Estado | I1: Facturable | J1: DIAS cotizado | K1: Prioridad | L1: Descripción | M1: Resolucion | N1: Envidado a factura
A2: OT-2026-001 | C2: LN | D2: PDSLL Terminal | E2: M.CORRECTIVO | F2: 03/02/2026 | G2: =_xlfn.MAXIFS(PLANIFICACION!B:B,PLANIFICACION!A:A,ORDENES!A2) -> 0 | H2: =_xlfn.XLOOKUP(A2,FACTURA!A:A,FACTURA!E:E,"NO PLANIFICADO") -> NO PLANIFICADO | I2: =IF(OR(E2="V.TECNICA",E2="PROYECTO",E2="IMPLEMENTACION"),"SI","NO") -> NO | J2: 2 | L2: instalacion de sistema de alarma | M2: quedo pendiente un panel | N2: =_xlfn.XLOOKUP(A2,FACTURA!A:A,FACTURA!F:F,"NO APLICA") -> NO APLICA
A3: OT-2026-002 | C3: dhl | D3: cuenca | E3: V.TECNICA | F3: 03/02/2026 | G3: =_xlfn.MAXIFS(PLANIFICACION!B:B,PLANIFICACION!A:A,ORDENES!A3) -> 0 | H3: =_xlfn.XLOOKUP(A3,FACTURA!A:A,FACTURA!E:E,"NO PLANIFICADO") -> NO PLANIFICADO | I3: =IF(OR(E3="V.TECNICA",E3="PROYECTO",E3="IMPLEMENTACION"),"SI","NO") -> SI | J3: 2 | K3: Alta | L3: instalacion de sistema de alarma | M3: finalizo la tarea | N3: =_xlfn.XLOOKUP(A3,FACTURA!A:A,FACTURA!F:F,"NO APLICA") -> NO APLICA
A4: OT-2026-003 | C4: LN | D4: PDSLL Terminal | E4: V.TECNICA | F4: 03/02/2026 | G4: =_xlfn.MAXIFS(PLANIFICACION!B:B,PLANIFICACION!A:A,ORDENES!A4) -> 0 | H4: =_xlfn.XLOOKUP(A4,FACTURA!A:A,FACTURA!E:E,"NO PLANIFICADO") -> NO PLANIFICADO | I4: =IF(OR(E4="V.TECNICA",E4="PROYECTO",E4="IMPLEMENTACION"),"SI","NO") -> SI | J4: 2 | K4: Alta | L4: Instalación alarma | M4: Pendiente panel | N4: =_xlfn.XLOOKUP(A4,FACTURA!A:A,FACTURA!F:F,"NO APLICA") -> NO APLICA
A5: OT-2026-004 | C5: LN | D5: guasmo | E5: V.TECNICA | F5: 46085 | G5: =_xlfn.MAXIFS(PLANIFICACION!B:B,PLANIFICACION!A:A,ORDENES!A5) -> 0 | H5: =_xlfn.XLOOKUP(A5,FACTURA!A:A,FACTURA!E:E,"NO PLANIFICADO") -> NO PLANIFICADO | I5: =IF(OR(E5="V.TECNICA",E5="PROYECTO",E5="IMPLEMENTACION"),"SI","NO") -> SI | J5: 2 | K5: MEDIA | L5: instalacion de sistema de alarma | M5: instalado | N5: =_xlfn.XLOOKUP(A5,FACTURA!A:A,FACTURA!F:F,"NO APLICA") -> NO APLICA
A6: OT-2026-005 | C6: LN | D6: PDSLL GUASMO SUR, GYE | E6: V.TECNICA | F6: 46091 | G6: =_xlfn.MAXIFS(PLANIFICACION!B:B,PLANIFICACION!A:A,ORDENES!A6) -> 0 | H6: =_xlfn.XLOOKUP(A6,FACTURA!A:A,FACTURA!E:E,"NO PLANIFICADO") -> NO PLANIFICADO | I6: =IF(OR(E6="V.TECNICA",E6="PROYECTO",E6="IMPLEMENTACION"),"SI","NO") -> SI | K6: MEDIA | N6: =_xlfn.XLOOKUP(A6,FACTURA!A:A,FACTURA!F:F,"NO APLICA") -> NO APLICA
A7: OT-2026-006 | B7: PORTOVIEJO | C7: LN | D7: PDSLL PORTOVIEJO, PTV | E7: PROYECTO | F7: 46106 | G7: =_xlfn.MAXIFS(PLANIFICACION!B:B,PLANIFICACION!A:A,ORDENES!A7) -> 46106 | H7: =_xlfn.XLOOKUP(A7,FACTURA!A:A,FACTURA!E:E,"NO PLANIFICADO") -> NO PLANIFICADO | I7: =IF(OR(E7="V.TECNICA",E7="PROYECTO",E7="IMPLEMENTACION"),"SI","NO") -> SI | J7: 1 | K7: MEDIA | L7: IMPLEMENTACIÓN DE REJA DE SEGURIDAD | N7: =_xlfn.XLOOKUP(A7,FACTURA!A:A,FACTURA!F:F,"NO APLICA") -> NO APLICA
A8: OT-2026-007 | B8: JIPIJAPA | C8: LN | D8: PDSLL HIPER JIPIJAPA, JPJ | E8: PROYECTO | F8: 46106 | G8: =_xlfn.MAXIFS(PLANIFICACION!B:B,PLANIFICACION!A:A,ORDENES!A8) -> 46106 | H8: =_xlfn.XLOOKUP(A8,FACTURA!A:A,FACTURA!E:E,"NO PLANIFICADO") -> NO PLANIFICADO | I8: =IF(OR(E8="V.TECNICA",E8="PROYECTO",E8="IMPLEMENTACION"),"SI","NO") -> SI | J8: 1 | K8: MEDIA | L8: CAMBIO NVR + IMPLEMENTACIÓN DE REJA DE SEGURIDAD | N8: =_xlfn.XLOOKUP(A8,FACTURA!A:A,FACTURA!F:F,"NO APLICA") -> NO APLICA
A9: OT-2026-008 | B9: JIPIJAPA | C9: LN | D9: PDSLL JIPIJAPA, JPJ | E9: PROYECTO | F9: 46106 | G9: =_xlfn.MAXIFS(PLANIFICACION!B:B,PLANIFICACION!A:A,ORDENES!A9) -> 46106 | H9: =_xlfn.XLOOKUP(A9,FACTURA!A:A,FACTURA!E:E,"NO PLANIFICADO") -> NO PLANIFICADO | I9: =IF(OR(E9="V.TECNICA",E9="PROYECTO",E9="IMPLEMENTACION"),"SI","NO") -> SI | J9: 1 | K9: MEDIA | L9: CAMBIO NVR + IMPLEMENTACIÓN DE REJA DE SEGURIDAD | N9: =_xlfn.XLOOKUP(A9,FACTURA!A:A,FACTURA!F:F,"NO APLICA") -> NO APLICA
A10: OT-2026-009 | B10: QUITO | C10: DUEÑO OFI UIO | D10: Oficina Quito | E10: V.TECNICA | F10: 46106 | G10: =_xlfn.MAXIFS(PLANIFICACION!B:B,PLANIFICACION!A:A,ORDENES!A10) -> 46106 | H10: =_xlfn.XLOOKUP(A10,FACTURA!A:A,FACTURA!E:E,"NO PLANIFICADO") -> NO PLANIFICADO | I10: =IF(OR(E10="V.TECNICA",E10="PROYECTO",E10="IMPLEMENTACION"),"SI","NO") -> SI | J10: 1 | K10: MEDIA | L10: CAMBIO DE CABLE DE RED | N10: =_xlfn.XLOOKUP(A10,FACTURA!A:A,FACTURA!F:F,"NO APLICA") -> NO APLICA
A11: OT-2026-010 | B11: QUITO | C11: LN | D11: PDSLL LA FLORIDA UIO | E11: PROYECTO | F11: 46106 | G11: =_xlfn.MAXIFS(PLANIFICACION!B:B,PLANIFICACION!A:A,ORDENES!A11) -> 46106 | H11: =_xlfn.XLOOKUP(A11,FACTURA!A:A,FACTURA!E:E,"NO PLANIFICADO") -> NO PLANIFICADO | I11: =IF(OR(E11="V.TECNICA",E11="PROYECTO",E11="IMPLEMENTACION"),"SI","NO") -> SI | J11: 1 | K11: MEDIA | L11: CAMBIO NVR + IMPLEMENTACIÓN DE REJA DE SEGURIDAD | N11: =_xlfn.XLOOKUP(A11,FACTURA!A:A,FACTURA!F:F,"NO APLICA") -> NO APLICA
A12: OT-2026-011 | B12: QUITO | C12: LN | D12: PDSLL VACA DE CASTRO | E12: PROYECTO | F12: 46106 | G12: =_xlfn.MAXIFS(PLANIFICACION!B:B,PLANIFICACION!A:A,ORDENES!A12) -> 46106 | H12: =_xlfn.XLOOKUP(A12,FACTURA!A:A,FACTURA!E:E,"NO PLANIFICADO") -> NO PLANIFICADO | I12: =IF(OR(E12="V.TECNICA",E12="PROYECTO",E12="IMPLEMENTACION"),"SI","NO") -> SI | J12: 1 | K12: MEDIA | L12: CAMBIO NVR + IMPLEMENTACIÓN DE REJA DE SEGURIDAD | N12: =_xlfn.XLOOKUP(A12,FACTURA!A:A,FACTURA!F:F,"NO APLICA") -> NO APLICA
A13: OT-2026-012 | B13: QUITO | C13: LN | D13: PDSLL COTOCOLLAO, UIO | E13: PROYECTO | F13: 46106 | G13: =_xlfn.MAXIFS(PLANIFICACION!B:B,PLANIFICACION!A:A,ORDENES!A13) -> 46106 | H13: =_xlfn.XLOOKUP(A13,FACTURA!A:A,FACTURA!E:E,"NO PLANIFICADO") -> NO PLANIFICADO | I13: =IF(OR(E13="V.TECNICA",E13="PROYECTO",E13="IMPLEMENTACION"),"SI","NO") -> SI | J13: 1 | K13: MEDIA | L13: IMPLEMENTACIÓN DE REJA DE SEGURIDAD | N13: =_xlfn.XLOOKUP(A13,FACTURA!A:A,FACTURA!F:F,"NO APLICA") -> NO APLICA
A14: OT-2026-013 | B14: LATACUNGA | C14: LN | D14: PDSLL LATACUNGA EXPRESS, LAT | E14: PROYECTO | F14: 46106 | G14: =_xlfn.MAXIFS(PLANIFICACION!B:B,PLANIFICACION!A:A,ORDENES!A14) -> 46106 | H14: =_xlfn.XLOOKUP(A14,FACTURA!A:A,FACTURA!E:E,"NO PLANIFICADO") -> NO PLANIFICADO | I14: =IF(OR(E14="V.TECNICA",E14="PROYECTO",E14="IMPLEMENTACION"),"SI","NO") -> SI | J14: 1 | K14: MEDIA | L14: CAMBIO NVR + IMPLEMENTACIÓN DE REJA DE SEGURIDAD | N14: =_xlfn.XLOOKUP(A14,FACTURA!A:A,FACTURA!F:F,"NO APLICA") -> NO APLICA
A15: OT-2026-014 | B15: AMBATO | C15: LN | D15: PDSLL AMBATO 1 | E15: PROYECTO | F15: 46106 | G15: =_xlfn.MAXIFS(PLANIFICACION!B:B,PLANIFICACION!A:A,ORDENES!A15) -> 46106 | H15: =_xlfn.XLOOKUP(A15,FACTURA!A:A,FACTURA!E:E,"NO PLANIFICADO") -> NO PLANIFICADO | I15: =IF(OR(E15="V.TECNICA",E15="PROYECTO",E15="IMPLEMENTACION"),"SI","NO") -> SI | J15: 1 | K15: MEDIA | L15: CAMBIO NVR + IMPLEMENTACIÓN DE REJA DE SEGURIDAD | N15: =_xlfn.XLOOKUP(A15,FACTURA!A:A,FACTURA!F:F,"NO APLICA") -> NO APLICA
A16: OT-2026-015 | B16: AMBATO | C16: LN | D16: PDSLL AKI EL CONDOR,AMB, LOCAL 14 | E16: PROYECTO | F16: 46106 | G16: =_xlfn.MAXIFS(PLANIFICACION!B:B,PLANIFICACION!A:A,ORDENES!A16) -> 46106 | H16: =_xlfn.XLOOKUP(A16,FACTURA!A:A,FACTURA!E:E,"NO PLANIFICADO") -> NO PLANIFICADO | I16: =IF(OR(E16="V.TECNICA",E16="PROYECTO",E16="IMPLEMENTACION"),"SI","NO") -> SI | J16: 1 | K16: MEDIA | L16: CAMBIO NVR + IMPLEMENTACIÓN DE REJA DE SEGURIDAD | N16: =_xlfn.XLOOKUP(A16,FACTURA!A:A,FACTURA!F:F,"NO APLICA") -> NO APLICA
A17: OT-2026-016 | B17: HUAQUILLAS | C17: LN | D17: PDSLL HUAQUILLAS | E17: PROYECTO | F17: 46106 | G17: =_xlfn.MAXIFS(PLANIFICACION!B:B,PLANIFICACION!A:A,ORDENES!A17) -> 46106 | H17: =_xlfn.XLOOKUP(A17,FACTURA!A:A,FACTURA!E:E,"NO PLANIFICADO") -> NO PLANIFICADO | I17: =IF(OR(E17="V.TECNICA",E17="PROYECTO",E17="IMPLEMENTACION"),"SI","NO") -> SI | J17: 1 | K17: MEDIA | L17: CAMBIO NVR + IMPLEMENTACIÓN DE REJA DE SEGURIDAD | N17: =_xlfn.XLOOKUP(A17,FACTURA!A:A,FACTURA!F:F,"NO APLICA") -> NO APLICA
A18: OT-2026-017 | B18: SANTA ROSA | C18: LN | D18: PDSLL SANTA ROSA | E18: PROYECTO | F18: 46106 | G18: =_xlfn.MAXIFS(PLANIFICACION!B:B,PLANIFICACION!A:A,ORDENES!A18) -> 46106 | H18: =_xlfn.XLOOKUP(A18,FACTURA!A:A,FACTURA!E:E,"NO PLANIFICADO") -> NO PLANIFICADO | I18: =IF(OR(E18="V.TECNICA",E18="PROYECTO",E18="IMPLEMENTACION"),"SI","NO") -> SI | J18: 1 | K18: MEDIA | L18: CAMBIO NVR + IMPLEMENTACIÓN DE REJA DE SEGURIDAD | N18: =_xlfn.XLOOKUP(A18,FACTURA!A:A,FACTURA!F:F,"NO APLICA") -> NO APLICA
A19: OT-2026-018 | B19: CUENCA | C19: LN | D19: PDSLL EL ARENAL EXPRESS, CUE | E19: PROYECTO | F19: 46106 | G19: =_xlfn.MAXIFS(PLANIFICACION!B:B,PLANIFICACION!A:A,ORDENES!A19) -> 46106 | H19: =_xlfn.XLOOKUP(A19,FACTURA!A:A,FACTURA!E:E,"NO PLANIFICADO") -> NO PLANIFICADO | I19: =IF(OR(E19="V.TECNICA",E19="PROYECTO",E19="IMPLEMENTACION"),"SI","NO") -> SI | J19: 1 | K19: MEDIA | L19: CAMBIO NVR + IMPLEMENTACIÓN DE REJA DE SEGURIDAD | N19: =_xlfn.XLOOKUP(A19,FACTURA!A:A,FACTURA!F:F,"NO APLICA") -> NO APLICA
A20: OT-2026-019 | B20: PASAJE | C20: LN | D20: PDSLL CC SHOPPING MINI PLUS PASAJE, PAS | E20: PROYECTO | F20: 46107 | G20: 46107 | H20: =_xlfn.XLOOKUP(A20,FACTURA!A:A,FACTURA!E:E,"NO PLANIFICADO") -> NO PLANIFICADO | I20: =IF(OR(E20="V.TECNICA",E20="PROYECTO",E20="IMPLEMENTACION"),"SI","NO") -> SI | J20: 1 | K20: MEDIA | L20: CAMBIO NVR + IMPLEMENTACIÓN DE REJA DE SEGURIDAD | N20: =_xlfn.XLOOKUP(A20,FACTURA!A:A,FACTURA!F:F,"NO APLICA") -> NO APLICA
A21: OT-2026-020 | B21: MONTECRISTI | C21: LN | D21: PDSLL MONTECRISTI HYBRIDO, MTC | E21: PROYECTO | F21: 46107 | G21: 46107 | H21: =_xlfn.XLOOKUP(A21,FACTURA!A:A,FACTURA!E:E,"NO PLANIFICADO") -> NO PLANIFICADO | I21: =IF(OR(E21="V.TECNICA",E21="PROYECTO",E21="IMPLEMENTACION"),"SI","NO") -> SI | J21: 1 | K21: MEDIA | L21: CAMBIO NVR + IMPLEMENTACIÓN DE REJA DE SEGURIDAD | N21: =_xlfn.XLOOKUP(A21,FACTURA!A:A,FACTURA!F:F,"NO APLICA") -> NO APLICA
A22: OT-2026-021 | B22: CHONE | C22: LN | D22: PDSLL CHONE | E22: PROYECTO | F22: 46107 | G22: 46107 | H22: =_xlfn.XLOOKUP(A22,FACTURA!A:A,FACTURA!E:E,"NO PLANIFICADO") -> NO PLANIFICADO | I22: =IF(OR(E22="V.TECNICA",E22="PROYECTO",E22="IMPLEMENTACION"),"SI","NO") -> SI | J22: 1 | K22: MEDIA | L22: CAMBIO NVR + IMPLEMENTACIÓN DE REJA DE SEGURIDAD | N22: =_xlfn.XLOOKUP(A22,FACTURA!A:A,FACTURA!F:F,"NO APLICA") -> NO APLICA
A23: OT-2026-022 | B23: CALCETA | C23: LN | D23: PDSLL CALCETA | E23: PROYECTO | F23: 46107 | G23: 46107 | H23: =_xlfn.XLOOKUP(A23,FACTURA!A:A,FACTURA!E:E,"NO PLANIFICADO") -> NO PLANIFICADO | I23: =IF(OR(E23="V.TECNICA",E23="PROYECTO",E23="IMPLEMENTACION"),"SI","NO") -> SI | J23: 1 | K23: MEDIA | L23: CAMBIO NVR + IMPLEMENTACIÓN DE REJA DE SEGURIDAD | N23: =_xlfn.XLOOKUP(A23,FACTURA!A:A,FACTURA!F:F,"NO APLICA") -> NO APLICA
A24: OT-2026-023 | B24: QUITO | C24: QUIFATEX | D24: QUIFATEX UIO | E24: V.TECNICA | F24: 46107 | G24: 46107 | H24: =_xlfn.XLOOKUP(A24,FACTURA!A:A,FACTURA!E:E,"NO PLANIFICADO") -> NO PLANIFICADO | I24: =IF(OR(E24="V.TECNICA",E24="PROYECTO",E24="IMPLEMENTACION"),"SI","NO") -> SI | J24: 1 | K24: MEDIA | L24: VISITA TÉCNICA PARA COTIZACIÓN | N24: =_xlfn.XLOOKUP(A24,FACTURA!A:A,FACTURA!F:F,"NO APLICA") -> NO APLICA
A25: OT-2026-024 | B25: QUITO | C25: LN | D25: PDSLL PLAZA TEATRO | E25: PROYECTO | F25: 46107 | G25: 46107 | H25: =_xlfn.XLOOKUP(A25,FACTURA!A:A,FACTURA!E:E,"NO PLANIFICADO") -> NO PLANIFICADO | I25: =IF(OR(E25="V.TECNICA",E25="PROYECTO",E25="IMPLEMENTACION"),"SI","NO") -> SI | J25: 1 | K25: MEDIA | L25: CAMBIO NVR | N25: =_xlfn.XLOOKUP(A25,FACTURA!A:A,FACTURA!F:F,"NO APLICA") -> NO APLICA
A26: OT-2026-025 | B26: PATATE | C26: LN | D26: PDSLL PATATE | E26: PROYECTO | F26: 46107 | G26: 46107 | H26: =_xlfn.XLOOKUP(A26,FACTURA!A:A,FACTURA!E:E,"NO PLANIFICADO") -> NO PLANIFICADO | I26: =IF(OR(E26="V.TECNICA",E26="PROYECTO",E26="IMPLEMENTACION"),"SI","NO") -> SI | J26: 1 | K26: MEDIA | L26: CAMBIO NVR + IMPLEMENTACIÓN DE REJA DE SEGURIDAD | N26: =_xlfn.XLOOKUP(A26,FACTURA!A:A,FACTURA!F:F,"NO APLICA") -> NO APLICA
A27: OT-2026-026 | B27: GUANO | C27: LN | D27: PDSLL GUANO | E27: PROYECTO | F27: 46107 | G27: 46107 | H27: =_xlfn.XLOOKUP(A27,FACTURA!A:A,FACTURA!E:E,"NO PLANIFICADO") -> NO PLANIFICADO | I27: =IF(OR(E27="V.TECNICA",E27="PROYECTO",E27="IMPLEMENTACION"),"SI","NO") -> SI | J27: 1 | K27: MEDIA | L27: CAMBIO NVR + IMPLEMENTACIÓN DE REJA DE SEGURIDAD | N27: =_xlfn.XLOOKUP(A27,FACTURA!A:A,FACTURA!F:F,"NO APLICA") -> NO APLICA
A28: OT-2026-027 | B28: GUAMOTE | C28: LN | D28: PDSLL GUAMOTE | E28: PROYECTO | F28: 46107 | G28: 46107 | H28: =_xlfn.XLOOKUP(A28,FACTURA!A:A,FACTURA!E:E,"NO PLANIFICADO") -> NO PLANIFICADO | I28: =IF(OR(E28="V.TECNICA",E28="PROYECTO",E28="IMPLEMENTACION"),"SI","NO") -> SI | J28: 1 | K28: MEDIA | L28: CAMBIO NVR + IMPLEMENTACIÓN DE REJA DE SEGURIDAD | N28: =_xlfn.XLOOKUP(A28,FACTURA!A:A,FACTURA!F:F,"NO APLICA") -> NO APLICA
A29: OT-2026-028 | B29: CUENCA | C29: LN | D29: PDSLL AV DON BOSCO CUENCA | E29: PROYECTO | F29: 46107 | G29: 46107 | H29: =_xlfn.XLOOKUP(A29,FACTURA!A:A,FACTURA!E:E,"NO PLANIFICADO") -> NO PLANIFICADO | I29: =IF(OR(E29="V.TECNICA",E29="PROYECTO",E29="IMPLEMENTACION"),"SI","NO") -> SI | J29: 1 | K29: MEDIA | L29: CAMBIO NVR + IMPLEMENTACIÓN DE REJA DE SEGURIDAD | N29: =_xlfn.XLOOKUP(A29,FACTURA!A:A,FACTURA!F:F,"NO APLICA") -> NO APLICA
A30: OT-2026-029 | B30: QUITO | C30: LN | D30: PDSLL MANUEL ESPINOZA, UIO | E30: PROYECTO | F30: 46108 | G30: 46107 | H30: =_xlfn.XLOOKUP(A30,FACTURA!A:A,FACTURA!E:E,"NO PLANIFICADO") -> NO PLANIFICADO | I30: =IF(OR(E30="V.TECNICA",E30="PROYECTO",E30="IMPLEMENTACION"),"SI","NO") -> SI | J30: 1 | K30: MEDIA | L30: CAMBIO NVR + IMPLEMENTACIÓN DE REJA DE SEGURIDAD | N30: =_xlfn.XLOOKUP(A30,FACTURA!A:A,FACTURA!F:F,"NO APLICA") -> NO APLICA
A31: OT-2026-030 | B31: QUITO | C31: LN | D31: PDSLL RIO COCA | E31: PROYECTO | F31: 46108 | G31: 46107 | H31: =_xlfn.XLOOKUP(A31,FACTURA!A:A,FACTURA!E:E,"NO PLANIFICADO") -> NO PLANIFICADO | I31: =IF(OR(E31="V.TECNICA",E31="PROYECTO",E31="IMPLEMENTACION"),"SI","NO") -> SI | J31: 1 | K31: MEDIA | L31: CAMBIO NVR + IMPLEMENTACIÓN DE REJA DE SEGURIDAD | N31: =_xlfn.XLOOKUP(A31,FACTURA!A:A,FACTURA!F:F,"NO APLICA") -> NO APLICA
... A38: OT-2026-037 | B38: CUENCA | C38: LN | D38: PDSLL SIGSIG CUENCA | E38: PROYECTO | F38: 46108 | G38: 46107 | H38: =_xlfn.XLOOKUP(A38,FACTURA!A:A,FACTURA!E:E,"NO PLANIFICADO") -> NO PLANIFICADO | I38: =IF(OR(E38="V.TECNICA",E38="PROYECTO",E38="IMPLEMENTACION"),"SI","NO") -> SI | J38: 1 | K38: MEDIA | L38: CAMBIO NVR + IMPLEMENTACIÓN DE REJA DE SEGURIDAD | N38: =_xlfn.XLOOKUP(A38,FACTURA!A:A,FACTURA!F:F,"NO APLICA") -> NO APLICA
A39: OT-2026-038 | H39: =_xlfn.XLOOKUP(A39,FACTURA!A:A,FACTURA!E:E,"NO PLANIFICADO") -> NO PLANIFICADO | I39: =IF(OR(E39="V.TECNICA",E39="PROYECTO",E39="IMPLEMENTACION"),"SI","NO") -> NO | K39: MEDIA | N39: =_xlfn.XLOOKUP(A39,FACTURA!A:A,FACTURA!F:F,"NO APLICA") -> NO APLICA
H40: =_xlfn.XLOOKUP(A40,FACTURA!A:A,FACTURA!E:E,"NO PLANIFICADO") -> NO PLANIFICADO | I40: =IF(OR(E40="V.TECNICA",E40="PROYECTO",E40="IMPLEMENTACION"),"SI","NO") -> NO | K40: MEDIA | N40: =_xlfn.XLOOKUP(A40,FACTURA!A:A,FACTURA!F:F,"NO APLICA") -> NO APLICA
H41: =_xlfn.XLOOKUP(A41,FACTURA!A:A,FACTURA!E:E,"NO PLANIFICADO") -> PLANIFICADA | I41: =IF(OR(E41="V.TECNICA",E41="PROYECTO",E41="IMPLEMENTACION"),"SI","NO") -> NO | K41: MEDIA | N41: =_xlfn.XLOOKUP(A41,FACTURA!A:A,FACTURA!F:F,"NO APLICA") -> NO APLICA
H42: =_xlfn.XLOOKUP(A42,FACTURA!A:A,FACTURA!E:E,"NO PLANIFICADO") -> NO PLANIFICADO | I42: =IF(OR(E42="V.TECNICA",E42="PROYECTO",E42="IMPLEMENTACION"),"SI","NO") -> NO | K42: MEDIA | N42: =_xlfn.XLOOKUP(A42,FACTURA!A:A,FACTURA!F:F,"NO APLICA") -> NO APLICA
H43: =_xlfn.XLOOKUP(A43,FACTURA!A:A,FACTURA!E:E,"NO PLANIFICADO") -> PLANIFICADA | I43: =IF(OR(E43="V.TECNICA",E43="PROYECTO",E43="IMPLEMENTACION"),"SI","NO") -> NO | K43: MEDIA | N43: =_xlfn.XLOOKUP(A43,FACTURA!A:A,FACTURA!F:F,"NO APLICA") -> NO APLICA
H44: =_xlfn.XLOOKUP(A44,FACTURA!A:A,FACTURA!E:E,"NO PLANIFICADO") -> PLANIFICADA | I44: =IF(OR(E44="V.TECNICA",E44="PROYECTO",E44="IMPLEMENTACION"),"SI","NO") -> NO | K44: MEDIA | N44: =_xlfn.XLOOKUP(A44,FACTURA!A:A,FACTURA!F:F,"NO APLICA") -> NO APLICA
H45: =_xlfn.XLOOKUP(A45,FACTURA!A:A,FACTURA!E:E,"NO PLANIFICADO") -> NO PLANIFICADO | I45: =IF(OR(E45="V.TECNICA",E45="PROYECTO",E45="IMPLEMENTACION"),"SI","NO") -> NO | K45: MEDIA | N45: =_xlfn.XLOOKUP(A45,FACTURA!A:A,FACTURA!F:F,"NO APLICA") -> 46102
H46: =_xlfn.XLOOKUP(A46,FACTURA!A:A,FACTURA!E:E,"NO PLANIFICADO") -> NO PLANIFICADO | I46: =IF(OR(E46="V.TECNICA",E46="PROYECTO",E46="IMPLEMENTACION"),"SI","NO") -> NO | K46: MEDIA | N46: =_xlfn.XLOOKUP(A46,FACTURA!A:A,FACTURA!F:F,"NO APLICA") -> 46102
...

Sheet PLANIFICACION
A1: ID_ORDEN | B1: Fecha | C1: Técnico | D1: Cliente | E1: Local | F1: Resolución
A2: OT-2026-006 | B2: 46106 | C2: JOEL LOZANO HERNAN SALZAR | D2: =_xlfn.XLOOKUP(Tabla1[[#This Row],[ ID_ORDEN ]],ORDENES!A:A,ORDENES!C:C) -> LN | E2: =_xlfn.XLOOKUP(Tabla1[[#This Row],[ ID_ORDEN ]],ORDENES!A:A,ORDENES!D:D) -> PDSLL PORTOVIEJO, PTV
A3: OT-2026-007 | B3: 46106 | C3: ENRIQUE RENDON MARIO TUMBACO | D3: =_xlfn.XLOOKUP(Tabla1[[#This Row],[ ID_ORDEN ]],ORDENES!A:A,ORDENES!C:C) -> LN | E3: =_xlfn.XLOOKUP(Tabla1[[#This Row],[ ID_ORDEN ]],ORDENES!A:A,ORDENES!D:D) -> PDSLL HIPER JIPIJAPA, JPJ
A4: OT-2026-008 | B4: 46106 | C4: ENRIQUE RENDON MARIO TUMBACO | D4: =_xlfn.XLOOKUP(Tabla1[[#This Row],[ ID_ORDEN ]],ORDENES!A:A,ORDENES!C:C) -> LN | E4: =_xlfn.XLOOKUP(Tabla1[[#This Row],[ ID_ORDEN ]],ORDENES!A:A,ORDENES!D:D) -> PDSLL JIPIJAPA, JPJ
A5: OT-2026-009 | B5: 46106 | C5: VICTOR CASPI | D5: =_xlfn.XLOOKUP(Tabla1[[#This Row],[ ID_ORDEN ]],ORDENES!A:A,ORDENES!C:C) -> DUEÑO OFI UIO | E5: =_xlfn.XLOOKUP(Tabla1[[#This Row],[ ID_ORDEN ]],ORDENES!A:A,ORDENES!D:D) -> Oficina Quito
A6: OT-2026-010 | B6: 46106 | C6: VICTOR CASPI | D6: =_xlfn.XLOOKUP(Tabla1[[#This Row],[ ID_ORDEN ]],ORDENES!A:A,ORDENES!C:C) -> LN | E6: =_xlfn.XLOOKUP(Tabla1[[#This Row],[ ID_ORDEN ]],ORDENES!A:A,ORDENES!D:D) -> PDSLL LA FLORIDA UIO
A7: OT-2026-011 | B7: 46106 | C7: VICTOR CASPI | D7: =_xlfn.XLOOKUP(Tabla1[[#This Row],[ ID_ORDEN ]],ORDENES!A:A,ORDENES!C:C) -> LN | E7: =_xlfn.XLOOKUP(Tabla1[[#This Row],[ ID_ORDEN ]],ORDENES!A:A,ORDENES!D:D) -> PDSLL VACA DE CASTRO
A8: OT-2026-012 | B8: 46106 | C8: VICTOR CASPI | D8: =_xlfn.XLOOKUP(Tabla1[[#This Row],[ ID_ORDEN ]],ORDENES!A:A,ORDENES!C:C) -> LN | E8: =_xlfn.XLOOKUP(Tabla1[[#This Row],[ ID_ORDEN ]],ORDENES!A:A,ORDENES!D:D) -> PDSLL COTOCOLLAO, UIO
A9: OT-2026-013 | B9: 46106 | C9: PABLO PINO | D9: =_xlfn.XLOOKUP(Tabla1[[#This Row],[ ID_ORDEN ]],ORDENES!A:A,ORDENES!C:C) -> LN | E9: =_xlfn.XLOOKUP(Tabla1[[#This Row],[ ID_ORDEN ]],ORDENES!A:A,ORDENES!D:D) -> PDSLL LATACUNGA EXPRESS, LAT
A10: OT-2026-014 | B10: 46106 | C10: PABLO PINO | D10: =_xlfn.XLOOKUP(Tabla1[[#This Row],[ ID_ORDEN ]],ORDENES!A:A,ORDENES!C:C) -> LN | E10: =_xlfn.XLOOKUP(Tabla1[[#This Row],[ ID_ORDEN ]],ORDENES!A:A,ORDENES!D:D) -> PDSLL AMBATO 1
A11: OT-2026-015 | B11: 46106 | C11: PABLO PINO | D11: =_xlfn.XLOOKUP(Tabla1[[#This Row],[ ID_ORDEN ]],ORDENES!A:A,ORDENES!C:C) -> LN | E11: =_xlfn.XLOOKUP(Tabla1[[#This Row],[ ID_ORDEN ]],ORDENES!A:A,ORDENES!D:D) -> PDSLL AKI EL CONDOR,AMB, LOCAL 14
A12: OT-2026-016 | B12: 46106 | C12: FRANK ESPINOZA | D12: =_xlfn.XLOOKUP(Tabla1[[#This Row],[ ID_ORDEN ]],ORDENES!A:A,ORDENES!C:C) -> LN | E12: =_xlfn.XLOOKUP(Tabla1[[#This Row],[ ID_ORDEN ]],ORDENES!A:A,ORDENES!D:D) -> PDSLL HUAQUILLAS
A13: OT-2026-017 | B13: 46106 | C13: FRANK ESPINOZA | D13: =_xlfn.XLOOKUP(Tabla1[[#This Row],[ ID_ORDEN ]],ORDENES!A:A,ORDENES!C:C) -> LN | E13: =_xlfn.XLOOKUP(Tabla1[[#This Row],[ ID_ORDEN ]],ORDENES!A:A,ORDENES!D:D) -> PDSLL SANTA ROSA
... A33: OT-2026-037 | B33: 46108 | C33: BENJAMIN OMNITRON | D33: =_xlfn.XLOOKUP(Tabla1[[#This Row],[ ID_ORDEN ]],ORDENES!A:A,ORDENES!C:C) -> LN | E33: =_xlfn.XLOOKUP(Tabla1[[#This Row],[ ID_ORDEN ]],ORDENES!A:A,ORDENES!D:D) -> PDSLL SIGSIG CUENCA
A34: =ORDENES!#REF! -> #REF! | D34: =_xlfn.XLOOKUP(Tabla1[[#This Row],[ ID_ORDEN ]],ORDENES!A:A,ORDENES!C:C) -> #REF! | E34: =_xlfn.XLOOKUP(Tabla1[[#This Row],[ ID_ORDEN ]],ORDENES!A:A,ORDENES!D:D) -> #REF!
A35: =ORDENES!#REF! -> #REF! | D35: =_xlfn.XLOOKUP(Tabla1[[#This Row],[ ID_ORDEN ]],ORDENES!A:A,ORDENES!C:C) -> #REF! | E35: =_xlfn.XLOOKUP(Tabla1[[#This Row],[ ID_ORDEN ]],ORDENES!A:A,ORDENES!D:D) -> #REF!
A36: =ORDENES!#REF! -> #REF! | D36: =_xlfn.XLOOKUP(Tabla1[[#This Row],[ ID_ORDEN ]],ORDENES!A:A,ORDENES!C:C) -> #REF! | E36: =_xlfn.XLOOKUP(Tabla1[[#This Row],[ ID_ORDEN ]],ORDENES!A:A,ORDENES!D:D) -> #REF!
A37: =ORDENES!#REF! -> #REF! | D37: =_xlfn.XLOOKUP(Tabla1[[#This Row],[ ID_ORDEN ]],ORDENES!A:A,ORDENES!C:C) -> #REF! | E37: =_xlfn.XLOOKUP(Tabla1[[#This Row],[ ID_ORDEN ]],ORDENES!A:A,ORDENES!D:D) -> #REF!
A38: =ORDENES!#REF! -> #REF! | D38: =_xlfn.XLOOKUP(Tabla1[[#This Row],[ ID_ORDEN ]],ORDENES!A:A,ORDENES!C:C) -> #REF! | E38: =_xlfn.XLOOKUP(Tabla1[[#This Row],[ ID_ORDEN ]],ORDENES!A:A,ORDENES!D:D) -> #REF!
A39: =ORDENES!#REF! -> #REF! | D39: =_xlfn.XLOOKUP(Tabla1[[#This Row],[ ID_ORDEN ]],ORDENES!A:A,ORDENES!C:C) -> #REF! | E39: =_xlfn.XLOOKUP(Tabla1[[#This Row],[ ID_ORDEN ]],ORDENES!A:A,ORDENES!D:D) -> #REF!
A40: =ORDENES!#REF! -> #REF! | D40: =_xlfn.XLOOKUP(Tabla1[[#This Row],[ ID_ORDEN ]],ORDENES!A:A,ORDENES!C:C) -> #REF! | E40: =_xlfn.XLOOKUP(Tabla1[[#This Row],[ ID_ORDEN ]],ORDENES!A:A,ORDENES!D:D) -> #REF!
A41: =ORDENES!#REF! -> #REF!
A42: =ORDENES!#REF! -> #REF!
A43: =ORDENES!#REF! -> #REF!
A44: =ORDENES!#REF! -> #REF!
A45: =ORDENES!#REF! -> #REF!
A46: =ORDENES!#REF! -> #REF!
A47: =ORDENES!#REF! -> #REF!
A48: =ORDENES!#REF! -> #REF!
A49: =ORDENES!#REF! -> #REF!
A50: =ORDENES!#REF! -> #REF!
A51: =ORDENES!#REF! -> #REF!
A52: =ORDENES!#REF! -> #REF!
... A81: =ORDENES!#REF! -> #REF!
D168: {=_xlfn.XLOOKUP(A168,ORDENES!A162:A250,ORDENES!C162:C250,ORDENES!A162:A250)} -> 0 | E168: {=_xlfn.XLOOKUP(A168,ORDENES!A162:A250,ORDENES!D162:D250,ORDENES!A162:A250)} -> 0
D169: {=_xlfn.XLOOKUP(A169,ORDENES!A163:A251,ORDENES!C163:C251,ORDENES!A163:A251)} -> 0 | E169: {=_xlfn.XLOOKUP(A169,ORDENES!A163:A251,ORDENES!D163:D251,ORDENES!A163:A251)} -> 0

Sheet HORAS
A3: AÑO | B3: MES | C3: TECNICO | D3: DIA | E3: N° | F3: TURNO | G3: INGRESO | H3: HORA DE ALMUERZO | I3: SALIDA | J3: HORAS TRABAJADAS | K3: EXCEDENTE | L3: OBSERVACIONES
A4: 2025 | B4: ABRIL | C4: HERNAN SALAZAR | D4: MARTES | E4: 1 | F4: 0.33333333 | G4: 0.35416667 | H4: 0.041666667 | I4: 0.8125 | J4: 0.41666667 | K4: 0.083333333 | L4: ISLA PAÑORA DE BALA0
A5: 2025 | B5: ABRIL | C5: HERNAN SALAZAR | D5: MIÉRCOLES | E5: 2 | F5: 0.33333333 | G5: 0.33333333 | H5: 0.041666667 | I5: 0.8125 | J5: 0.4375 | K5: 0.10416667 | L5: HOSPITAL ROBERTO GILBERTH
A6: 2025 | B6: ABRIL | C6: HERNAN SALAZAR | D6: JUEVES | E6: 3 | F6: 0.33333333 | G6: 0.33333333 | H6: 0.041666667 | I6: 0.8125 | J6: 0.4375 | K6: 0.10416667 | L6: HOSPITAL ROBERTO GILBERTH
A7: 2025 | B7: ABRIL | C7: HERNAN SALAZAR | D7: VIERNES | E7: 4 | F7: 0.33333333 | G7: 0.33333333 | H7: 0.041666667 | I7: 0.77083333 | J7: 0.39583333 | K7: 0.0625 | L7: HOSPITAL ROBERTO GILBERTH
A8: 2025 | B8: ABRIL | C8: HERNAN SALAZAR | D8: SÁBADO | E8: 5 | F8: 0 | G8: 0 | H8: 0 | I8: 0 | J8: 0 | K8: 0 | L8: HOSPITAL ROBERTO GILBERTH
A9: 2025 | B9: ABRIL | C9: HERNAN SALAZAR | D9: DOMINGO | E9: 6 | F9: 0 | G9: 0 | H9: 0 | I9: 0 | J9: 0 | K9: 0 | L9: HOSPITAL ROBERTO GILBERTH
A10: 2025 | B10: ABRIL | C10: HERNAN SALAZAR | D10: LUNES | E10: 7 | F10: 0.33333333 | G10: 0.33333333 | H10: 0.041666667 | I10: 0.6875 | J10: 0.3125 | K10: -00:30:00 | L10: HOSPITAL ROBERTO GILBERTH
A11: 2025 | B11: ABRIL | C11: HERNAN SALAZAR | D11: MARTES | E11: 8 | F11: 0.33333333 | G11: 0.33333333 | H11: 0.041666667 | I11: 0.6875 | J11: 0.3125 | K11: -00:30:00 | L11: HOSPITAL ROBERTO GILBERTH
A12: 2025 | B12: ABRIL | C12: HERNAN SALAZAR | D12: MIÉRCOLES | E12: 9 | F12: 0.33333333 | G12: 0.33333333 | H12: 0.041666667 | I12: 0.625 | J12: 0.25 | K12: -02:00:00 | L12: HOSPITAL ROBERTO GILBERTH
A13: 2025 | B13: ABRIL | C13: HERNAN SALAZAR | D13: JUEVES | E13: 10 | F13: 0.33333333 | G13: 0.33333333 | H13: 0.041666667 | I13: 0.625 | J13: 0.25 | K13: -02:00:00 | L13: HOSPITAL ROBERTO GILBERTH
A14: 2025 | B14: ABRIL | C14: HERNAN SALAZAR | D14: VIERNES | E14: 11 | F14: 0.33333333 | G14: 0.33333333 | H14: 0.041666667 | I14: 0.58333333 | J14: 0.20833333 | K14: -03:00:00 | L14: HOSPITAL ROBERTO GILBERTH

Sheet FACTURA
A1: ID_ORDEN | B1: CLIENTE | C1: LOCAL | D1: TIPO | E1: Estado Facturación | F1: Fecha Envío
A2: {=_xlfn._xlws.FILTER(ORDENES!A2:E990,ISNUMBER(MATCH(ORDENES!E2:E990,{"V.TECNICA";"PROYECTO";"IMPLEMENTACION"},0)))} -> #VALUE! | E2: NO INICIADA | F2: 46101
E3: PLANIFICADA | F3: 46102
E4: PROCESO | F4: 46103
E5: FINALIZADO | F5: 46104
E6: PLANIFICADA
E7: PLANIFICADA
E8: PLANIFICADA
E9: PLANIFICADA
E10: PLANIFICADA
E11: PLANIFICADA
E12: PLANIFICADA
E13: PLANIFICADA
E14: PLANIFICADA
E15: PLANIFICADA
E16: PLANIFICADA
E17: PLANIFICADA
... E37: PLANIFICADA

Sheet PROYECTO NVR
B2: FECHA | C2: 2DA FECHA | D2: PROVINCIA | E2: PUNTO DE LA SUERTE | F2: CAMBIO NVR | G2: IMP CAM EXT | H2: IMP REJA DE SEG | I2: EQUIPO FECHA 1 | J2: EQUIPO FECHA 2 | K2: NOVEDADES PLANNER | L2: OBSERVACIONES | N2: EQUIPOS DT360
B3: 46101 | C3: 46106 | D3: Ambato | E3: PDSLL AMBATO 1 | F3: X | H3: X | I3: PABLO PINOS Y STEVE VILLACRES | N3: PABLO PINOS Y STEVE VILLACRES | O3: EQUIPO UIO
B4: 46101 | D4: Ambato | E4: PDSLL AKI EL CONDOR,AMB, LOCAL 14 | F4: X | H4: X | I4: PABLO PINOS Y STEVE VILLACRES | N4: BENJAMIN ESCANDON | O4: TEC CUE
B5: 46107 | D5: Babahoyo | E5: PDSLL BABAHOYO | F5: 46100 | H5: X | I5: HERNAN SALAZAR | N5: JORGE CARRILLO | O5: TEC LOJA
B6: 46099 | D6: BALZAR | E6: PDSLL MI COMISARIATO BALZAR, BLZ | F6: X | G6: X | H6: X | I6: EDWIN QUILUMBA | L6: No se realizó el cambio del NVR porque ya existe un NVR del mismo modelo, solo se aplicó las Analíticas.
B7: 46104 | D7: Bolivar | E7: PDSLL AKI GUARANDA | F7: X | H7: X | I7: PABLO PINOS Y STEVE VILLACRES
B8: 46104 | D8: Bolivar | E8: PDSLL SAN MIGUEL DE BOLIVAR | F8: X | H8: X | I8: PABLO PINOS Y STEVE VILLACRES
B9: 46106 | D9: CALCETA | E9: PDSLL CALCETA | F9: X | H9: X | I9: LUIS ASTERIO LOPEZ | K9: OPL SANTA ELENA - NO FUNCIONA PERIFONEA - SE SOLICITA CAMBIO DE BOCINA DAÑO EN LA MISMA, INDICO ANTERIORMENTE CARLOS PILLASAGUA
B10: 46099 | D10: Cayambe | E10: PDSLL CAYAMBE | F10: X | H10: X | I10: PABLO PINOS Y STEVE VILLACRES
B11: 46102 | D11: Chimborazo | E11: PDSLL GUANO | F11: X | H11: X | I11: PABLO PINOS Y STEVE VILLACRES
B12: 46107 | D12: CHONE | E12: PDSLL CHONE | F12: X | H12: X | I12: LUIS ASTERIO LOPEZ
B13: 46107 | C13: 46105 | D13: CUENCA | E13: PDSLL CUENCA, CUE | F13: X | H13: X | I13: BENJAMIN OMNITRON
B14: 46099 | C14: 46106 | D14: CUENCA | E14: PDSLL EL ARENAL EXPRESS, CUE | F14: X | H14: X | I14: BENJAMIN OMNITRON | N14: DETALLE | O14: CANT
B15: 46106 | C15: 46107 | D15: CUENCA | E15: PDSLL AV DON BOSCO CUENCA | F15: X | H15: X | I15: BENJAMIN OMNITRON | N15: NVR | O15: 55
B16: 46100 | C16: 46108 | D16: CUENCA | E16: PDSLL SIGSIG CUENCA | F16: X | H16: X | I16: BENJAMIN OMNITRON | N16: CAMARAS | O16: =3*2 -> 6
B17: 46107 | D17: Daule | E17: PDSLL PLAZA TIA LA JOYA, DAU | F17: 46098 | H17: X | L17: No se realizó el cambio del NVR porque ya existe un NVR del mismo modelo, solo se aplicó las Analíticas | N17: REJAS DE SEGURIDAD | O17: =56*2 -> 112
B18: 46106 | D18: Daule | E18: PDSLL PIAZZA VILLA CLUB, DAU | F18: 46099 | H18: X | K18: OPL BINGO GARZOTA - SALE ELIMINADA LA ALARMA EN LA CONSOLA QUE LE BRINDA SERVICIO AL OPERADOR
B19: 46104 | D19: Daule | E19: PDSLL DAULE, DAU | F19: 46100 | H19: X | I19: JOEL LOZANO | K19: PDVLL PATATE - NO TENEMOS VISUAL DE LA CAMARA DEL COUNTER EL RESTO DE CAMARAS ESTAN OPERATIVAS
B20: 46104 | D20: Daule | E20: PDSLL AKI DAULE, DAU | F20: 46100 | G20: X | H20: X | I20: JOEL LOZANO
B21: 46092 | C21: 46093 | D21: Duran | E21: PDSLL AKI PRIMAVERA DURAN | F21: 46093 | H21: X | I21: JOEL LOZANO
B22: 46092 | C22: 46093 | D22: Duran | E22: PDSLL PLAZA TIA DURAN, # L-23 | F22: ? | H22: X | I22: JOEL LOZANO | K22: PDSIL TERMINAL TERRESTRE MANTA - NO TIENE BATERIA EL TECLADO POR ENDE NO PUEDEN APERTURAR Y CERRAR EL PUNTO
B23: 46092 | C23: 46093 | D23: Duran | E23: PDSLL GRAN AKI DURAN | F23: ? | H23: X | I23: JOEL LOZANO
D24: Duran | E24: PDSLL ELOY ALFARO 1, DUR | F24: N/A | H24: X
B25: 46091 | D25: Empalme | E25: PDSLL EL EMPALME | F25: 46100 | G25: X | H25: X | I25: ENRIQUE RENDON
B26: 46092 | D26: EMPALME | E26: PDSLL MI COMISARIATO, EL EMPALME, LOCAL 1 | F26: X | G26: X | H26: X | I26: EDWIN QUILUMBA | L26: No se realizó el cambio del NVR porque ya existe un NVR del mismo modelo, solo se aplicó las Analíticas
B27: 46108 | D27: Esmeraldas | E27: PDSLL ESMERALDAS | F27: X | H27: X | I27: PABLO PINOS Y STEVE VILLACRES
B28: 46107 | D28: Esmeraldas | E28: PDSLL AKI QUININDE | F28: X | H28: X | I28: PABLO PINOS Y STEVE VILLACRES
B29: 46102 | D29: Guamote | E29: PDSLL GUAMOTE | F29: X | H29: X | I29: PABLO PINOS Y STEVE VILLACRES
D30: Guayaquil | E30: PDSLL GUASMO SUR, GYE | F30: 46058 | H30: X | I30: M. TUMBACO
B31: 46085 | C31: 46091 | D31: Guayaquil | E31: PDSLL PLAZA SAN EDUARDO, GYE, CALLE RODRIGUEZ BONIN | F31: 46085 | H31: X | I31: BRYAN GUERRERO | K31: REVISAR CONTACTO MAGNETICO ZONA 1 SE ACTIVA DESPUES DEL ARMADO
B32: 46086 | C32: 46094 | D32: Guayaquil | E32: PDSLL MERCADO CENTRAL 6 DE MARZO, GYE | F32: 46085 | H32: x | I32: KEVIN HIDALGO
B33: 46085 | C33: 46092 | D33: Guayaquil | E33: PDSLL SAUCES 6, GYE | F33: 46085 | H33: 46098 | I33: HERNAN SALAZAR
B34: 46086 | C34: 46094 | D34: Guayaquil | E34: PDSLL PLAZA TIA EL MAESTRO, GYE | F34: 46086 | H34: X | I34: ENRIQUE RENDON
B35: 46086 | C35: 46094 | D35: Guayaquil | E35: PDSLL GOMEZ RENDON Y GARCIA MORENO, GYE | F35: 46086 | H35: X | I35: BRYAN GUERRERO
B36: 46087 | C36: 46094 | D36: Guayaquil | E36: PDSLL TIA MUCHO LOTE 2, GYE | F36: 46086 | G36: X | H36: x | I36: ENRIQUE RENDON
B37: 46087 | C37: 46097 | D37: Guayaquil | E37: PDSLL PLAZA TIA BASTION, GYE | F37: 46086 | G37: X | H37: x | I37: CARLOS PILLASAGUA
B38: 46086 | C38: 46094 | D38: Guayaquil | E38: PDSLL CC TIA EL CAMINO, GYE, KM 19.5 VIA A DAULE | F38: 46086 | H38: X | I38: CARLOS PILLASAGUA
B39: 46086 | C39: 46094 | D39: Guayaquil | E39: PDSLL PLAZA ORELLANA GYE | F39: 46086 | H39: X | I39: HERNAN SALAZAR | L39: No se realizó el cambio del NVR porque ya existe un NVR del mismo modelo, solo se aplicó las Analíticas
B40: 46086 | C40: 46097 | D40: Guayaquil | E40: PDSLL CARCHI Y 1 DE MAYO, GYE | F40: 46087 | H40: x | I40: JOEL LOZANO
B41: 46087 | C41: 46097 | D41: Guayaquil | E41: PDSLL MI COMISARIATO FLORIDA, GYE | F41: 46087 | G41: X | H41: x | I41: BRYAN GUERRERO
...

Sheet PRO HUMOS

Sheet PRO LECTORAS

Sheet MANT ANUAL
A1: PROYECTO | C1: PLAN DE MANTENIMIENTO ANUAL
A3: SERIE | B3: TIPO DE LOCAL | C3: LOCAL | D3: CIUDAD | E3: FECHA DE IMPLEMENTACION | F3: INF | G3: FECHA DE MANTENIMIENTO 2024 | H3: INF | I3: FECHA DE MANTENIMINETO 2025 | J3: INF | K3: FECHA DE MANTENIMINETO 2026 | L3: INF | M3: FECHA M.PREV FINAL | N3: OBSERVACION
A4: 1 | B4: LOCAL CC | C4: PDSLL MALL DEL SUR, GYE | D4: Guayaquil | E4: 44986 | G4: 45635 | I4: 45845 | K4: 46210
A5: 2 | B5: LOCAL | C5: PDSLL PEDRO CARBO Y SUCRE | D5: Guayaquil | E5: 44998 | G5: 45364 | I5: 45799 | K5: 46164
A6: 3 | B6: LOCAL | C6: PDSLL 9 DE OCTUBRE BOULEVARD, GYE | D6: Guayaquil | E6: 44998 | G6: 45364 | I6: 45796 | K6: 46161
A7: 4 | B7: LOCAL | C7: PDSLL 9 DE OCTUBRE 427, GYE | D7: Guayaquil | E7: 44998 | G7: 45364 | I7: 45798 | K7: 46163
A8: 5 | B8: LOCAL | C8: PDSLL BAHIA | D8: Guayaquil | E8: 44998 | G8: 45364 | I8: 45926 | K8: 46291
A9: 6 | B9: LOCAL | C9: PDSLL BOYACA, GYE | D9: Guayaquil | E9: 44998 | G9: 45364 | I9: 45798 | K9: 46163
A10: 7 | B10: LOCAL | C10: PDSLL LA GARZOTA, GYE | D10: Guayaquil | E10: 44998 | G10: 45364 | I10: 45804 | K10: 46169
A11: 8 | B11: LOCAL | C11: PDSLL ALBOTEC, GYE | D11: Guayaquil | E11: 44998 | G11: 45364 | I11: 45803 | K11: 46168
A12: 9 | B12: LOCAL | C12: PDSLL PLAZA DE LA SUERTE GYE CHILE Y LUQUE | D12: Guayaquil | E12: 44998 | G12: 45364 | I12: 45960 | K12: 46325
A13: 10 | B13: LOCAL | C13: PDSLL ELOY ALFARO 1,DUR | D13: Duran | E13: 44998 | G13: 45364 | I13: 45876 | K13: 46241
A14: 11 | B14: LOCAL | C14: PDSLL JIPIJAPA, JPJ | D14: Manabi | E14: 44998 | G14: 45364 | I14: 45911 | K14: 46276
A15: 12 | B15: LOCAL | C15: PDSLL EL ARENAL EXPRESS, CUE | D15: Cuenca | E15: 44998 | G15: 45364 | I15: 45862 | K15: 46227
... A21: 18 | B21: LOCAL | C21: PDSLL COTOCOLLAO, UIO | D21: Quito | E21: 44998 | G21: 45364 | I21: 45905 | K21: 46270
A22: 19 | B22: LOCAL | C22: PDSLL LA CAROLINA, UIO | D22: Quito | E22: 44998 | G22: 45364 | I22: 45674 | K22: 46048 | M22: 46066 | N22: PROBLEMA SENSOR MAGNETICO - CONTROL DE ACCESO
A23: 20 | B23: LOCAL | C23: PDSLL MARIANA DE JESUS, UIO | D23: Quito | E23: 44998 | G23: 45364 | I23: 45677 | K23: 46051 | M23: 46066 | N23: El amplificador de perifoneo no funciona hay que reemplazarlo.
A24: 21 | B24: LOCAL | C24: PDSLL MERCURY, UIO | D24: Quito | E24: 44998 | G24: 45364 | I24: 45670 | K24: 46066 | M24: 46071 | N24: HAY QUE CAMBIAR DE TECLADO
A25: 22 | B25: LOCAL | C25: PDSLL OLMEDO EXPRESS, UIO | D25: Quito | E25: 44998 | G25: 45364 | I25: 45673 | K25: 46051 | M25: 46066 | N25: el botón de pánico no funciona pero hay señal en el cable se debe cambiar el botón de pánico y el amplificador de perifoneo se debe cambiar la fuente ya que no le apreta la ajuga y se debe poner un objeto para que aprete
A26: 23 | B26: LOCAL | C26: PDSLL SOLANDA, UIO | D26: Quito | E26: 44998 | G26: 45364 | I26: 45678 | K26: 46074 | M26: 46086
A27: 24 | B27: LOCAL | C27: PDSLL CUENCA, CUE | D27: Cuenca | E27: 44998 | G27: 45364 | I27: 45729 | K27: 46094 | M27: 46094
A28: 25 | B28: LOCAL | C28: PDSLL C. S. EMELEC, GYE | D28: Guayaquil | E28: 44998 | G28: 45364 | I28: 45803 | K28: 46168
A29: 26 | B29: LOCAL | C29: PDSLL VELEZ, GYE | D29: Guayaquil | E29: 44998 | G29: 45364 | I29: 45803 | K29: 46168
A30: 27 | B30: LOCAL | C30: PDSLL CARCELEN, UIO | D30: Quito | E30: 44998 | G30: 45364 | I30: 45680 | K30: 46049 | M30: 46049
A31: 28 | B31: LOCAL | C31: PDSLL COREA, UIO, COREA 126 | D31: Quito | E31: 44998 | G31: 45364 | I31: 45673 | K31: 46048 | M31: 46072 | N31: uno de los botones de pánico adicional se realiza medición de continuidad con multímetro pero no hay comunicación por lo que se debe cambiar el cable ya que posiblemente está fisurado y se tiene el error de recepción de alertas del botón de pánico
A32: 29 | B32: LOCAL | C32: PDSLL ZONA SORTEO MATRIZ DE LOTERÍA NACIONAL | D32: Guayaquil | E32: 44998 | G32: 45364 | I32: 45817 | K32: 46182
A33: 30 | B33: LOCAL | C33: PDSLL CENTRO HISTORICO | D33: Quito | E33: 45059 | G33: 45364 | I33: 45672 | K33: 46050 | N33: una camara es el problema que no da visual
A34: 31 | B34: LOCAL | C34: PDSLL LA SALESIANA, UIO | D34: Quito | E34: 45059 | G34: 45364 | I34: 45674 | K34: 46048 | M34: 46048
A35: 32 | B35: LOCAL | C35: PDSLL REAL AUDIENCIA, UIO | D35: Quito | E35: 45059 | G35: 45364 | I35: 45680 | K35: 46076 | M35: 46071
A36: 33 | B36: LOCAL | C36: PDSLL AKI EL CONDOR,AMB, LOCAL 14 | D36: Ambato | E36: 45153 | G36: 45519 | I36: 45884 | K36: 46249
A37: 34 | B37: LOCAL | C37: PDSLL MARTHA BUCARAM, UIO | D37: Quito | E37: 45241 | G37: 45635 | I37: 45667 | K37: 46052 | M37: 46052
A38: 35 | B38: LOCAL | C38: PDSLL PLAZA TIA BASTION | D38: Guayaquil | E38: 45244 | G38: 45635 | I38: 45805 | K38: 46170
A39: 36 | B39: LOCAL | C39: PDSLL SAMBORONDÓN, SAM | D39: Guayaquil | E39: 45245 | G39: 45635 | I39: 46000 | K39: 46365
A40: 37 | B40: LOCAL | C40: PDSLL SAUCES 6, GYE | D40: Guayaquil | E40: 45252 | G40: 45618 | I40: 45786 | K40: 46151
A41: 38 | B41: LOCAL | C41: PDSLL PLAZA DEL VALLE EXPRESS, UIO | D41: Quito | E41: 45259 | G41: 45635 | I41: 45677 | K41: 46073 | M41: 46073
A42: 39 | B42: LOCAL | C42: PDSLL EL INCA EXPRESS, UIO | D42: Quito | E42: 45264 | G42: 45635 | I42: 45666 | K42: 46048 | M42: 46071 | N42: PERDIDA DE BATERIA EN EL PANEL
A43: 40 | B43: LOCAL | C43: PDSLL PLAZA FOCH, UIO | D43: Quito | E43: 45266 | G43: 45635 | I43: 45678 | K43: 46051 | N43: Se recomienda hacer reubicación de botón de pánico ya que lo presionan al abrir la puerta del baño.
A44: 41 | B44: LOCAL | C44: PDSLL PORTETE 2, GYE | D44: Guayaquil | E44: 45269 | G44: 45635 | I44: 45789 | K44: 46154
A45: 42 | B45: ISLA CC | C45: PDSIL CC CITY MALL 1, GYE P1 #S/N | D45: Guayaquil | E45: 45345 | G45: N/A | I45: 45817 | K45: 46182
A46: 43 | B46: ISLA CC | C46: PDSIL CC CITY MALL 2, GYE PB #S/N | D46: Guayaquil | E46: 45345 | G46: N/A | I46: 45946 | K46: 46311
...
